File: lib/Aluminum_loops.txt
File Path: C:\MTS TestSuite\Data Files\Test Run 9 2-5-2014 4 26 50 PM\DAQ- Time, … - (Timed).txt
Test: MTS EM Tension (Extensometer)and outputs stress trigger n stress loops neal 2
Test Run: Test Run 9
Date: 2/5/2014 4:17:57 PM


Time 	Load 	Crosshead 	Extensometer 	Strain 	Stress
sec	kN	mm	mm	mm/mm	kN/mm²
0.123999997973442	-0.00969915580749512	0.00190587525139563	4.70525023388291E-05	1.87333478152141E-06	-0.000157381265625
1.12399995326996	0.778229797363281	0.051458631787682	0.008022549081943	0.000315562356263399	0.012627779
2.12400007247925	1.58109643554688	0.101368736068252	0.0154023982759099	0.000606045941822231	0.025655322
3.12400007247925	2.3900048828125	0.151219282997772	0.0224155755859101	0.000882220221683383	0.0387809
4.12400007247925	3.196462890625	0.201069837203249	0.0291046799247852	0.0011455996427685	0.05186672
5.12400007247925	3.99682885742188	0.250860815867782	0.0355291558662429	0.0013984905090183	0.064853684
6.12400007247925	4.78886083984375	0.300651823636144	0.041689596400829	0.00164107116870582	0.077705424
7.12400007247925	5.57189404296875	0.350442802300677	0.0476138811791316	0.00187433743849397	0.090411144
8.12399959564209	6.34410205078125	0.400293356506154	0.0533247512066737	0.00209920923225582	0.102941208
9.12399959564209	7.10030078125	0.449965242296457	0.0588342227274552	0.00231610285118222	0.115211504
10.1239995956421	7.84504052734375	0.499815796501935	0.0641820442979224	0.00252665253356099	0.127295864
11.1239995956421	8.5826376953125	0.549547199625522	0.0694367481628433	0.0027334492187947	0.13926432
12.1239995956421	9.3028310546875	0.599397753830999	0.0745436118450016	0.00293466146104038	0.150950384
13.1239995956421	10.0082080078125	0.649188761599362	0.0795322848716751	0.00313100451603532	0.162396032
14.1239995956421	10.70423046875	0.698979769367725	0.0844154492369853	0.00332324090413749	0.173689904
15.1239995956421	11.3927431640625	0.748770718928427	0.0892179159563966	0.00351239205338061	0.184861904
16.1240005493164	12.0746015625	0.798621273133904	0.0939594465307891	0.00369900022633374	0.195925936
17.1240005493164	11.9309150390625	0.789151468779892	0.0930596652324311	0.00366393686272204	0.193594432
18.1240005493164	11.1592822265625	0.739420007448643	0.0878580831340514	0.00345909735187888	0.181073696
19.1240005493164	10.3955537109375	0.689688604325056	0.0826717805466615	0.00325499335303903	0.168681216
20.1240005493164	9.6375634765625	0.639838050119579	0.0774906147853471	0.00305100157856941	0.156381856
21.1240005493164	8.8792236328125	0.589927949476987	0.0722609474905767	0.00284509360790253	0.144076816
22.1240005493164	8.118654296875	0.539958302397281	0.0669580258545466	0.00263632484711707	0.1317356
23.1240005493164	7.3580615234375	0.490107748191804	0.0615936660324223	0.00242515257559717	0.119394008
24.1240005493164	6.5967060546875	0.440257164882496	0.0561376982659567	0.00221042381599545	0.107040032
25.1240005493164	5.83569384765625	0.390406639780849	0.0505877869727556	0.00199183914810419	0.094691632
26.1240005493164	5.069345703125	0.340496510034427	0.0448886858066544	0.00176745373755693	0.082256648
27.1240005493164	4.30515869140625	0.290586409391835	0.039046753954608	0.0015375156654045	0.069856736
28.1240005493164	3.54009936523438	0.240735869738273	0.0330066432070453	0.00129969161935151	0.057442664
29.1240005493164	2.77659497070313	0.190766193554737	0.0267601408268092	0.00105379626620561	0.045053824
30.1240005493164	2.01444812011719	0.140915653901175	0.0202527407964226	0.000797594839241356	0.03268701
31.1240005493164	1.259005859375	0.0910055387066677	0.013417973605101	0.000528581847902387	0.020428988
32.1240005493164	0.509521820068359	0.0412145527661778	0.00616465285929735	0.000242912181420252	0.0082676465
33.1240005493164	0.15069856262207	0.017927139197127	0.00245779119723011	9.64049540925771E-05	0.00244527775
34.1240005493164	0.948720275878906	0.0675990086165257	0.0103148204289027	0.000405789847718552	0.015394206
35.1240005493164	1.75613757324219	0.117509116535075	0.0176204939634772	0.000693460402544588	0.02849559
36.1240005493164	2.56427001953125	0.167240548762493	0.0245458413701272	0.000966118997894228	0.041608576
37.1240005493164	3.37432543945313	0.217150663957	0.0311939111270476	0.00122784450650215	0.054752768
38.1240005493164	4.17613720703125	0.266882096184418	0.0375661547877826	0.00147870264481753	0.067763192
39.1240005493164	4.9701064453125	0.316792196827009	0.0436852351413108	0.00171964836772531	0.080646368
40.1240005493164	5.75318896484375	0.366464082617313	0.0495671411044896	0.0019512438448146	0.093352888
41.1240005493164	6.523455078125	0.416255061281845	0.0552372584934346	0.00217448570765555	0.10585144
42.1240005493164	7.27766796875	0.465926947072148	0.0607239599048626	0.00239054742269218	0.11808952
43.1240005493164	8.02334765625	0.51583704771474	0.0660475343465805	0.00260007148608565	0.130189128
44.1240005493164	8.7550302734375	0.565628055483103	0.0712564724381082	0.00280518271028996	0.142061616
45.1240005493164	9.4765029296875	0.615419005043805	0.0763375574024394	0.0030052054207772	0.153768448
46.1240005493164	10.185578125	0.665210012812167	0.0812997459433973	0.00320060132071376	0.165274096
47.1240005493164	10.890318359375	0.715060567017645	0.0862115775817074	0.00339392572641373	0.176709408
48.1240005493164	11.58359375	0.764851574786007	0.091008136223536	0.0035828691907227	0.187958704
49.1240005493164	12.2735810546875	0.814582977909595	0.0957691299845465	0.0037702766712755	0.199154624
50.1240005493164	12.9410546875	0.864373985677958	0.100376841146499	0.00395162124186754	0.209985248
51.1240005493164	12.2705791015625	0.818037369754165	0.0958923774305731	0.00377548323012888	0.19910592
52.1240005493164	11.5091259765625	0.768246420193464	0.0907778958207928	0.00357412081211805	0.186750368
53.1240005493164	10.75699609375	0.718455412425101	0.0856857222970575	0.00337366759777069	0.17454608
54.1240005493164	10.0068994140625	0.668664404656738	0.0805709642008878	0.00317232543602586	0.1623748
55.1240005493164	9.257064453125	0.618813850451261	0.0754416105337441	0.00297035509720445	0.150207776
56.1240005493164	8.50416015625	0.568963296245784	0.0702247125445865	0.00276493583805859	0.137990928
57.1240005493164	7.74576220703125	0.519112742040306	0.0648979766992852	0.00255527440458536	0.125684944
58.1240005493164	6.98709716796875	0.4691430949606	0.0595054807490669	0.00234298803843558	0.113374632
59.1240005493164	6.22595361328125	0.419292540755123	0.0540122928214259	0.00212670164182782	0.101024096
60.1240005493164	5.4613779296875	0.369322893675417	0.0483793846797198	0.00190493033733219	0.08861788
61.1240005493164	4.69862744140625	0.319472339469939	0.0426373662776314	0.00167887518182397	0.076241272
62.1240005493164	3.93475341796875	0.269621785264462	0.0367132597602904	0.0014456738717854	0.063846432
63.1240005493164	3.1709111328125	0.219771231058985	0.0305902904074173	0.00120466551743448	0.051452108
64.1240005493164	2.40848608398438	0.169801569427364	0.0242106470977888	0.000953381124418229	0.039080784
65.1240005493164	1.64999072265625	0.120010583486874	0.0175626610143809	0.000691691122483462	0.02677322
66.1240005493164	0.896079162597656	0.0700409145792946	0.0105241297205794	0.000414681882830337	0.014540036
67.1240005493164	0.155149978637695	0.0202499250008259	0.00305983417092648	0.000120790238725021	0.00251750775
68.1240005493164	0.532517211914063	0.0446093908976763	0.00688785166857997	0.000270927790552378	0.008640776
69.1240005493164	1.3359130859375	0.0944003841141239	0.0144274927151855	0.000567694194614887	0.021676906
70.1240005493164	2.14591162109375	0.144310484756716	0.0215246818697779	0.000847154704388231	0.034820176
71.1240005493164	2.95732080078125	0.194101477973163	0.0283128010778455	0.00111442559864372	0.047986332
72.1240005493164	3.76468017578125	0.243892471189611	0.0348368448612746	0.00137125549372286	0.061086776
73.1240005493164	4.5641328125	0.293683464406058	0.0410664397350047	0.00161659473087639	0.07405892
74.1240005493164	5.3543125	0.343414896633476	0.0470809463877231	0.00185336114373058	0.0868806
75.1240005493164	6.132787109375	0.393265450838953	0.0528741475136485	0.00208140444010496	0.099512352
76.1240005493164	6.8984052734375	0.442996883066371	0.0584652516408823	0.00230158912017941	0.111935488
77.1240005493164	7.64840673828125	0.492847408168018	0.063853854953777	0.00251374230720103	0.124105232
78.1240005493164	8.387685546875	0.542638415936381	0.0691339882905595	0.00272162025794387	0.136100976
79.1240005493164	9.11496484375	0.592429423704743	0.0742737902328372	0.00292402738705277	0.147902016
80.1240005493164	9.8327353515625	0.642220373265445	0.079296063631773	0.00312169315293431	0.159548768
81.1240005493164	10.5400400390625	0.692011381033808	0.0842148729134351	0.00331533676944673	0.171025696
82.1240005493164	11.23914453125	0.741742842365056	0.0890701776370406	0.00350655615329742	0.182369568
83.1240005493164	11.9312333984375	0.791593338362873	0.0938394005061127	0.00369426142424345	0.1935996
84.1240005493164	12.618078125	0.841384346131235	0.0985624792519957	0.00388019112870097	0.204744528
85.1240005493164	13.2856875	0.891175353899598	0.103158577985596	0.00406118156388402	0.21557736
86.1240005493164	13.2112470703125	0.886827590875328	0.102751473605167	0.00404550367966294	0.214369456
87.1240005493164	12.457529296875	0.837036583106965	0.0977278832579032	0.0038477499037981	0.202139424
88.1240005493164	11.7085400390625	0.787245575338602	0.0926713837543502	0.00364866387099028	0.189986112
89.1240005493164	10.96526953125	0.737395021133125	0.0876632038853131	0.00345152011141181	0.177925584
90.1240005493164	10.2235751953125	0.687604071572423	0.0826252507977188	0.00325315189547837	0.16589064
91.1240005493164	9.4782939453125	0.63769391272217	0.0775262960814871	0.00305248191580176	0.153797504
92.1240005493164	8.729478515625	0.587783812079579	0.0723562552593648	0.00284894928336143	0.141647008
93.1240005493164	7.9765146484375	0.537873711436987	0.0670891022309661	0.00264152814634144	0.1294292
94.1240005493164	7.22217138671875	0.48802318633534	0.0617577097727917	0.00243161548860371	0.117189016
95.1240005493164	6.465658203125	0.438172632129863	0.056320262956433	0.00221760477870703	0.104913616
96.1240005493164	5.70341552734375	0.388262531487271	0.0507369331899099	0.00199769833125174	0.092545248
97.1240005493164	4.94116943359375	0.338352401740849	0.0450440675194841	0.00177366880234331	0.080176824
98.1240005493164	4.17725439453125	0.288442301098257	0.0391770554415416	0.00154259765986353	0.06778132
99.1240005493164	3.4147890625	0.238591761444695	0.0331128758261912	0.00130386918317527	0.05540934
100.124000549316	2.6530888671875	0.188681646250188	0.0268358417088166	0.00105680467095226	0.043049776
101.124000549316	1.89211291503906	0.138831092044711	0.0202696537598968	0.000798264925833791	0.030701964
102.124000549316	1.13952478027344	0.0889209914021194	0.0133959019876784	0.000527672469615936	0.018490254
103.124000549316	0.395331207275391	0.0391300018236507	0.00609080143476604	0.000239988003158942	0.006414757
104.124000549316	0.274147857666016	0.0310895884467755	0.0048125157263712	0.000189185579074547	0.0044484015
105.124000549316	1.07424133300781	0.0807614633231424	0.0125658789329464	0.000494438223540783	0.017430946
106.124000549316	1.88463842773438	0.130612010252662	0.0197931694856379	0.000778960646130145	0.03058068
107.124000549316	2.69612158203125	0.18040300346911	0.026674055334297	0.00104992056731135	0.043748036
108.124000549316	3.5066123046875	0.230253557674587	0.0332743438775651	0.00130973348859698	0.056899292
109.124000549316	4.30991748046875	0.279984989902005	0.0395939678128343	0.00155856984201819	0.069933952
110.124000549316	5.1045439453125	0.329775968566537	0.0457010537502356	0.00179897411726415	0.082827784
111.124000549316	5.88856591796875	0.379626522772014	0.0515491374244448	0.00202924339100719	0.095549552
112.124000549316	6.66056689453125	0.429477076977491	0.0572123826714233	0.00225226231850684	0.108076256
113.124000549316	7.4159052734375	0.479208509204909	0.0626714099780656	0.00246727955527604	0.120332592
114.124000549316	8.1580712890625	0.528939941432327	0.0679718796163797	0.00267583946697414	0.132375192
115.124000549316	8.8889794921875	0.578790495637804	0.0731343170627952	0.00287912483327091	0.14423512
116.124000549316	9.61023828125	0.628521898761392	0.0782176794018596	0.00307918665930629	0.155938464
117.124000549316	10.3191650390625	0.678372452966869	0.0831481665954925	0.00327335833571851	0.167441712
118.124000549316	11.02166015625	0.728103914298117	0.088013919594232	0.00346492696553469	0.178840608
119.124000549316	11.7149873046875	0.778014014940709	0.092801041319035	0.00365340732969344	0.19009072
120.124000549316	12.4056123046875	0.827745418064296	0.0975518050836399	0.00384038453921676	0.201297008
121.124000549316	13.083884765625	0.877595972269773	0.102195110230241	0.00402328884229064	0.212302848
122.124000549316	13.7378916015625	0.927327433601022	0.10670509072952	0.00420084083452821	0.222914944
123.124000549316	14.0739482421875	0.955260416958481	0.109122353023849	0.00429636379703879	0.228367904
124.124000549316	13.3409140625	0.905588502064347	0.104233244201168	0.00410384079441428	0.216473472
125.124000549316	12.6161435546875	0.855797552503645	0.0993886205833405	0.00391317252069712	0.204713152
126.124000549316	11.8822490234375	0.806066091172397	0.0944763669394888	0.00371975312009454	0.192804768
127.124000549316	11.1509970703125	0.756275141611695	0.0895218836376444	0.00352473650127649	0.180939264
128.123992919922	10.41554296875	0.706364982761443	0.0845503745949827	0.00332900392822921	0.169005568
129.123992919922	9.677677734375	0.656395335681736	0.0794926745584235	0.00312990299426019	0.157032752
130.123992919922	8.936056640625	0.606604327913374	0.0743984855944291	0.00292929168790579	0.144999008
131.123992919922	8.18785302734375	0.556634680833668	0.0691808018018492	0.00272389058955014	0.13285844
132.123992919922	7.43444970703125	0.50678412662819	0.0638832862023264	0.00251532951369882	0.120633504
133.123992919922	6.68095703125	0.456814479548484	0.0584904009883758	0.00230295583605766	0.108407112
134.123992919922	5.92360205078125	0.407023471780121	0.0529779790667817	0.00208602752536535	0.096118056
135.123992919922	5.16415283203125	0.357172917574644	0.0473403924843296	0.00186400965321809	0.083795016
136.123992919922	4.4028564453125	0.307262816932052	0.041536277421983	0.00163558928761631	0.071442008
137.123992919922	3.64099731445313	0.257293169852346	0.0355492993548978	0.00139979540836066	0.05907986
138.123992919922	2.88061206054688	0.207383054657839	0.0293669763777871	0.00115644210018218	0.046741632
139.123992919922	2.12161206054688	0.157532500452362	0.0229122306336649	0.00090232933871448	0.034425884
140.123992919922	1.36824279785156	0.107622392533813	0.0161449333972996	0.000635897216852754	0.022201498
141.123992919922	0.621486694335938	0.0577718419663142	0.00896661276783561	0.000353311625076458	0.01008442
142.123992919922	0.0184210357666016	0.018641841961653	0.00271736553258961	0.0001066944168997	0.00029890496875
143.123992919922	0.818555725097656	0.0681350429658778	0.0107419346022652	0.000422673125285655	0.013282119
144.123992919922	1.62805432128906	0.11804514360847	0.0181220966624096	0.000713213114067912	0.026417274
145.123992919922	2.44004711914063	0.167836144100875	0.0250992616201984	0.000987917883321643	0.0395929
146.123992919922	3.25428344726563	0.217746244743466	0.0317949052259792	0.00125156121794134	0.052804932
147.123992919922	4.05925317382813	0.267477676970884	0.0381951213057619	0.0015035382239148	0.0658666
148.123992919922	4.8584501953125	0.317328231176361	0.0443617027485743	0.00174628931563348	0.0788346
149.123992919922	5.646451171875	0.367059663403779	0.0502903822052758	0.00197970541194081	0.091620928
150.123992919922	6.42122509765625	0.416791095631197	0.0560016815143172	0.00220459373667836	0.104192632
151.123992919922	7.1825947265625	0.466522527858615	0.0615172539255582	0.00242172600701451	0.116546832
152.123992919922	7.9299521484375	0.516432628501207	0.0668693464831449	0.00263242027722299	0.128673664
153.123992919922	8.6658330078125	0.566223636269569	0.0720891111996025	0.00283796549774706	0.140614272
154.123992919922	9.390392578125	0.616014585830271	0.0771787817939185	0.00303835771046579	0.152371184
155.123992919922	10.1011162109375	0.665805593598634	0.0821319408714771	0.0032333810813725	0.1639036
156.123992919922	10.8058193359375	0.715656147804111	0.087028689449653	0.00342614436522126	0.175338304
157.123992919922	11.499404296875	0.765447155572474	0.0918143196031451	0.00361460377462208	0.186592608
158.123992919922	12.18802734375	0.815178558696061	0.0965324288699776	0.00380037352442741	0.197766416
159.123992919922	12.8682822265625	0.865029112901539	0.101213285233825	0.00398460729047656	0.208804416
160.123992919922	13.5376103515625	0.914820120669901	0.105804021586664	0.00416529132053256	0.21966512
161.123992919922	14.15307421875	0.964670674875379	0.110055771074258	0.00433274265378714	0.229651824
162.123992919922	14.68300390625	1.01434253156185	0.113871166831814	0.00448297336697578	0.238250608
163.123992919922	14.3027509765625	0.990757369436324	0.111479079350829	0.00438911095261574	0.232080512
164.123992919922	13.5980224609375	0.940966361667961	0.106782448710874	0.00420415494590998	0.220645392
165.123992919922	12.9218720703125	0.891234900336713	0.10227010352537	0.00402658991515636	0.209673984
166.123992919922	12.2410625	0.841384346131235	0.097709140391089	0.00384697620756924	0.198626976
167.123992919922	11.517544921875	0.791533791925758	0.0928586232475936	0.00365605391561985	0.186886976
168.123992919922	10.7923623046875	0.741564144846052	0.087956759671215	0.00346306338906288	0.175119952
169.123992919922	10.063880859375	0.691773137077689	0.0830048520583659	0.00326807866804302	0.163299408
170.123992919922	9.3298525390625	0.641863036435097	0.0779762922320515	0.00307015399448574	0.151388848
171.123992919922	8.5905224609375	0.59201248222962	0.0728572267689742	0.00286864140070975	0.139392272
172.123992919922	7.84396240234375	0.542042835149914	0.0676181880407967	0.00266245589591563	0.127278368
173.123992919922	7.094365234375	0.492132734507322	0.0623230444034562	0.00245387456379831	0.115115192
174.123992919922	6.34194580078125	0.442282180301845	0.0568984178244136	0.00224034348502755	0.102906224
175.123992919922	5.584919921875	0.392372050555423	0.0513394588779192	0.00202144286595285	0.090622504
176.123992919922	4.82877978515625	0.342461949912831	0.0456593697890639	0.00179777573794127	0.07835316
177.123992919922	4.07015234375	0.292611395707354	0.0398219053749926	0.00156797282397747	0.066043452
178.123992919922	3.3135390625	0.242760856053792	0.0337921628670301	0.00133069371804595	0.053766432
179.123992919922	2.5563330078125	0.1928507554112	0.0275130951195024	0.00108343211468309	0.041479788
180.123992919922	1.80176928710938	0.142940640216693	0.0209635927603813	0.00082564220065251	0.029236022
181.123992919922	1.05449182128906	0.0929709785850719	0.0140890824695816	0.000554920407012105	0.017110486
182.123992919922	0.316642242431641	0.0431799853686243	0.00676398622090346	0.000266555842244998	0.0051379275
183.123992919922	0.353801300048828	0.0452645363111515	0.00705865886629908	0.000277629587799311	0.005740881
184.123992919922	1.1579736328125	0.0950555258896202	0.0147294394992059	0.00057956506498158	0.01878961
185.123992919922	1.97164624023438	0.144965641084127	0.0219262947211973	0.000862910877913237	0.031992494
186.123992919922	2.78559887695313	0.194756619748659	0.0287537204712862	0.00113175925798714	0.045199924
187.123992919922	3.59723950195313	0.244547612965107	0.035321219911566	0.00139035016763955	0.058369836
188.123992919922	4.40007568359375	0.294338591629639	0.0416070834035054	0.00163785670883954	0.07139688
189.123992919922	5.1955927734375	0.344129599398002	0.0476605346193537	0.00187620706856251	0.084305168
190.123992919922	5.97905419921875	0.393980153603479	0.0534855862497352	0.00210552825592458	0.09701784
191.123992919922	6.74982177734375	0.443711585830897	0.059128251450602	0.00232759956270456	0.109524536
192.123992919922	7.50551904296875	0.493562140036374	0.0645585241727531	0.00254147103987634	0.121786696
193.123992919922	8.247544921875	0.543233996722847	0.0698451622156426	0.00274963886477053	0.133827016
194.123992919922	8.977443359375	0.593144097365439	0.0749938189983368	0.00295232539065182	0.14567056
195.123992919922	9.6962529296875	0.642875558696687	0.0800142224761657	0.00315008265897632	0.15733416
196.123992919922	10.4024052734375	0.692726112902164	0.0849328571348451	0.00334361125715077	0.1687924
197.123992919922	11.099814453125	0.742397969588637	0.0897587233339436	0.00353363412432373	0.180108752
198.123992919922	11.78981640625	0.792308070231229	0.0945083156693727	0.00372062739916146	0.191304928
199.123992919922	12.472130859375	0.842099077999592	0.0991951674222946	0.00390505418181419	0.202376352
200.123992919922	13.1460537109375	0.891949632205069	0.103828664578032	0.0040875356644392	0.213311616
201.123992919922	13.798283203125	0.941681035328656	0.108274049125612	0.00426255166530609	0.22389488
202.123992919922	14.3896875	0.991531531326473	0.112381654616911	0.00442431680858135	0.233491168
203.123992919922	14.8933720703125	1.0413225973025	0.116034556413069	0.00456819962710142	0.241664112
204.123992919922	15.122798828125	1.09117315150797	0.117982643132564	0.00464498111978173	0.245386848
205.123992919922	15.20888671875	1.1410831939429	0.118910596938804	0.00468150386586785	0.246783728
206.123992919922	15.28511328125	1.19099335279316	0.119763142720331	0.00471505103632808	0.248020608
207.123992919922	15.290203125	1.24108209274709	0.120051758131012	0.00472641829401255	0.2481032
208.123992919922	15.300279296875	1.2910517398268	0.120319076813757	0.00473692780360579	0.248266704
209.123992919922	15.30994921875	1.34102150332183	0.120527336548548	0.00474516302347183	0.2484236
210.123992919922	15.307330078125	1.39093154575676	0.120638782391325	0.00474951276555657	0.248381104
211.123992919922	15.30359375	1.44096079748124	0.120732089271769	0.0047532576136291	0.24832048
212.123992919922	15.3142080078125	1.49093044456095	0.120918040920515	0.00476052053272724	0.248492704
213.123992919922	15.331201171875	1.5408406034112	0.121118369861506	0.00476838927716017	0.248768448
214.123992919922	15.3370419921875	1.5908102504909	0.121264565677848	0.00477417092770338	0.248863216
215.123992919922	15.3774384765625	1.64089899044484	0.121644065075088	0.00478915544226766	0.249518704
216.123992919922	15.3982666015625	1.6909878468141	0.121915043564513	0.0047998339869082	0.249856672
217.123992919922	15.401814453125	1.74089788924903	0.12205408711452	0.00480530643835664	0.24991424
218.123992919922	14.8986943359375	1.71981414314359	0.11873546463903	0.00467481184750795	0.241750464
219.123992919922	14.2802939453125	1.66996358893812	0.11462267866591	0.00451277149841189	0.231716128
220.123992919922	13.876388671875	1.62011303473264	0.111913679575082	0.00440614484250546	0.22516224
221.123992919922	13.5990498046875	1.57014338765293	0.110049280920066	0.00433267559856176	0.220662064
222.123992919922	13.3974765625	1.52017374057323	0.108706022729166	0.00427976110950112	0.21739128
223.123992919922	13.201896484375	1.47020409349352	0.107422740256879	0.00422936305403709	0.214217744
224.123992919922	13.0921181640625	1.42035353928804	0.106672021502163	0.00419975118711591	0.212436448
225.123992919922	13.0219580078125	1.37026468291879	0.106218692963012	0.00418185396119952	0.211298
226.123992919922	12.9424140625	1.32017594296485	0.105797291325871	0.00416524475440383	0.210007296
227.123992919922	13.2060673828125	1.27020629588515	0.107571089756675	0.00423315493389964	0.214285424
228.123992919922	15.907869140625	1.21987925376743	0.138519768370315	0.00545375468209386	0.258125616
229.123992919922	15.11315625	1.17008830420673	0.133273482788354	0.0052471999078989	0.245230384
230.123992919922	14.3653115234375	1.12017814535648	0.128328611026518	0.00505247805267572	0.233095648
231.123992919922	13.617310546875	1.070327591151	0.123378180433065	0.00485769473016262	0.220958368
232.123992919922	12.871072265625	1.02035794407129	0.118444695544895	0.00466342270374298	0.208849696
233.123992919922	12.125478515625	0.97056693630293	0.113515379780438	0.00446934811770916	0.196751472
234.123992919922	11.38054296875	0.920656835660338	0.108601765532512	0.00427586538717151	0.184663936
235.123992919922	10.6338857421875	0.870865886099637	0.103670827229507	0.00408168835565448	0.172548464
236.123992919922	9.885333984375	0.820955727249384	0.0987093735602684	0.00388635415583849	0.160402256
237.123992919922	9.1384208984375	0.771105231251568	0.0937510121730156	0.0036912236828357	0.148282624
238.123992919922	8.3891806640625	0.721195072401315	0.0887607748154551	0.0034947597887367	0.136125232
239.123992919922	7.63615283203125	0.671284971758723	0.0836778126540594	0.00329461158253253	0.123906392
240.123992919922	6.87756396484375	0.621374871116132	0.0785490119596943	0.00309273251332343	0.111597312
241.123992919922	6.12053515625	0.571524316910654	0.0733681881683879	0.002888711867854	0.099313552
242.123992919922	5.3608125	0.521614216268063	0.0681023302604444	0.00268140551634133	0.086986072
243.123992919922	4.60695654296875	0.471763691166416	0.0627780391369015	0.00247179041616619	0.074753792
244.123992919922	3.84729736328125	0.421913136960939	0.057331893913215	0.00225735199637711	0.062427344
245.123992919922	3.09269213867188	0.371943460777402	0.0517584230692592	0.00203790166415274	0.050182904
246.123992919922	2.33940966796875	0.32203336013481	0.0460370829387102	0.00181267946027219	0.037959928
247.123992919922	1.59190637207031	0.272182805929333	0.0401420256821439	0.00158058432862163	0.025830726
248.123992919922	0.8511875	0.222332251723856	0.0339940452249721	0.00133861845824867	0.013811611
249.123992919922	0.118336387634277	0.172362590092234	0.0275163329206407	0.00108362745959312	0.00192016
250.123992919922	0.593469665527344	0.201546310563572	0.031357463740278	0.00123430578969419	0.009629808
251.123992919922	1.42817553710938	0.251277728239074	0.0379798220819794	0.00149499904364347	0.023173984
252.123992919922	2.26009985351563	0.301128282444552	0.0442851196567062	0.00174330279696733	0.036673024
253.123992919922	3.09101806640625	0.350978836650029	0.0503876035509165	0.00198350264690816	0.05015574
254.123992919922	3.91537060546875	0.400829390855506	0.0563134053663816	0.0022168739233166	0.06353192
255.123992919922	4.7303203125	0.450560823082924	0.0620611972408369	0.00244315760210156	0.076755528
256.123992919922	5.53506591796875	0.500411377288401	0.0676754352753051	0.00266420235857368	0.08981356
257.123992919922	6.33142138671875	0.550142780411989	0.0731490654288791	0.00287965079769492	0.102735448
258.123992919922	7.118935546875	0.599993334617466	0.0785303927841596	0.00309145450592041	0.11551388
259.123992919922	7.8958115234375	0.649784342385829	0.0837996994960122	0.00329898647032678	0.128119688
260.123992919922	8.65937890625	0.699456199072301	0.0889545990503393	0.00350197078660131	0.140509552
261.123992919922	9.4113427734375	0.749247206840664	0.0940249592531472	0.00370162888430059	0.152711136
262.123992919922	10.1513037109375	0.799157307483256	0.099004631920252	0.00389762478880584	0.164717952
263.123992919922	10.8812587890625	0.848948315251619	0.10393193224445	0.00409156270325184	0.176562416
264.123992919922	11.60454296875	0.898679718375206	0.108807827928104	0.00428357627242804	0.188298624
265.123992919922	12.315048828125	0.948470726143569	0.113658192276489	0.004474479239434	0.199827488
266.123992919922	13.0209140625	0.998321222141385	0.118487179861404	0.00466461339965463	0.211281072
267.123992919922	13.708873046875	1.04817177634686	0.123246369184926	0.00485201692208648	0.22244408
268.123992919922	14.3842509765625	1.09784374944866	0.127977225929499	0.00503833498805761	0.23340296
269.123992919922	15.0313935546875	1.14763469900936	0.13260891137179	0.00522063532844186	0.24390368
270.123992919922	15.6440458984375	1.19736616034061	0.137223600177094	0.00540235172957182	0.253844752
271.123992919922	15.8696044921875	1.2204748345539	0.139726049383171	0.00550125818699598	0.257504736
272.123992919922	15.093765625	1.1708625825122	0.134663278004155	0.00530183967202902	0.244915744
273.123992919922	14.3340302734375	1.12101202830672	0.129671534523368	0.00510539906099439	0.232588064
274.123992919922	13.57682421875	1.0712209623307	0.124687343486585	0.00490919873118401	0.220301424
275.123992919922	12.8237822265625	1.02137040812522	0.119724893011153	0.00471379980444908	0.208082352
276.123992919922	12.0697109375	0.97157945856452	0.114773793029599	0.00451875803992152	0.195846576
277.123992919922	11.316744140625	0.921609811484814	0.109807726403233	0.00432337122038007	0.18362872
278.123992919922	10.563390625	0.871759257279336	0.104862017906271	0.00412860000506043	0.171404592
279.123992919922	9.8074599609375	0.821908703073859	0.0998571413219906	0.00393161596730351	0.15913864
280.123992919922	9.053287109375	0.772058148868382	0.094874638307374	0.00373540795408189	0.146901216
281.123992919922	8.296775390625	0.72214804822579	0.0898467696970329	0.00353745417669415	0.13462584
282.123992919922	7.535044921875	0.672297494020313	0.0847610353957862	0.0033372170291841	0.122265792
283.123992919922	6.76670556640625	0.622387393377721	0.0795886007836089	0.00313362898305058	0.109798496
284.123992919922	6.000619140625	0.572536839172244	0.0743855271139182	0.00292883021757007	0.09736776
285.123992919922	5.23084423828125	0.522626738529652	0.0690922170178965	0.00272030127234757	0.084877168
286.123992919922	4.46492822265625	0.47271660878323	0.0637543125776574	0.00251022656448185	0.0724492
287.123992919922	3.69412670898438	0.422925630118698	0.0582612155994866	0.00229394785128534	0.059941952
288.123992919922	2.92677514648438	0.372955953935161	0.0526659132447094	0.00207372708246112	0.047490688
289.123992919922	2.16165063476563	0.323105399729684	0.046926608774811	0.00184773118235171	0.03507556
290.123992919922	1.401220703125	0.273195299087092	0.0409939093515277	0.00161417201161385	0.022736606
291.123992919922	0.648046325683594	0.22334475943353	0.0348476896760985	0.00137214746791869	0.010515385
292.123992919922	0.0132826642990112	0.182547111762688	0.0293010743916966	0.00115332833956927	0.000215528296875
293.123992919922	0.854685974121094	0.232218983001076	0.0361765596608166	0.00142409314867109	0.013868378
294.123992919922	1.69003039550781	0.282009976217523	0.0425872458436061	0.00167644664179534	0.027422916
295.123992919922	2.52458471679688	0.331860530423	0.0487741381220985	0.00191998342052102	0.040964632
296.123992919922	3.35512036132813	0.381711084628478	0.0547663548786659	0.00215597241185606	0.05444114
297.123992919922	4.17665771484375	0.431442516855896	0.0605878230999224	0.00238510267809033	0.06777164
298.123992919922	4.99257080078125	0.481173949083313	0.0662729144096375	0.00260893465019763	0.08101088
299.123992919922	5.795951171875	0.530964927747846	0.0717917791916989	0.00282619381323457	0.09404676
300.123992919922	6.5921962890625	0.580815481953323	0.0772192215663381	0.00303992512635887	0.106966856
301.123992919922	7.3769296875	0.63054688507691	0.0825170282041654	0.0032485225237906	0.119700168
302.123992919922	8.150416015625	0.680397439282388	0.0877311467775144	0.00345375947654247	0.132250976
303.123992919922	8.91176171875	0.730128900613636	0.0928367953747511	0.00365482340566814	0.144604784
304.123992919922	9.65989453125	0.780039001256227	0.0978438838501461	0.00385190639644861	0.156744208
305.123992919922	10.396634765625	0.8297108579427	0.102781057648826	0.00404631346464157	0.168698768
306.123992919922	11.1263232421875	0.879561412148178	0.107664993265644	0.00423860130831599	0.180538896
307.123992919922	11.8467314453125	0.929292873479426	0.112519446702208	0.00442969752475619	0.192228448
308.123992919922	12.5605283203125	0.979202915914357	0.117358795250766	0.00462025590240955	0.20381072
309.123992919922	13.2666611328125	1.02887488901615	0.122149809612893	0.00480879563838243	0.215268624
310.123992919922	13.962462890625	1.07872532680631	0.12691029405687	0.00499627506360412	0.226558912
311.123992919922	14.6456484375	1.12851639278233	0.131647640955634	0.00518272817134857	0.237644464
312.123992919922	15.312455078125	1.17830734234303	0.136335904244334	0.00536735495552421	0.248464272
313.123992919922	15.9311875	1.22809840831906	0.14098102110438	0.00555028393864632	0.258504
314.123992919922	16.40237109375	1.27782975323498	0.146458682138473	0.00576574727892876	0.266149552
315.123992919922	16.549017578125	1.32785900495946	0.153628207044676	0.00604805955663323	0.268529088
316.123992919922	16.631537109375	1.37776916380972	0.161161136929877	0.00634460942819715	0.269868064
317.123992919922	15.98598828125	1.34399940725416	0.158880313392729	0.00625533796846867	0.2593932
318.123992919922	15.226193359375	1.29426794592291	0.153916436829604	0.00605992041528225	0.24706456
319.123992919922	14.4738779296875	1.24447699636221	0.148978491779417	0.00586548633873463	0.23485728
320.123992919922	13.7268427734375	1.19468593038619	0.144080579048023	0.00567264202982187	0.222735664
321.123992919922	12.982388671875	1.14477588795125	0.139219540869817	0.0054812477901578	0.210655936
322.123992919922	12.23917578125	1.09492533374578	0.134353758767247	0.00528967892751098	0.198596352
323.123992919922	11.4938720703125	1.04501517489552	0.129472362459637	0.00509755406528711	0.186502848
324.123992919922	10.7478046875	0.995105132460594	0.124589336337522	0.00490528624504805	0.174396944
325.123992919922	10.0010126953125	0.945135427173227	0.119693933811504	0.00471256114542484	0.16227928
326.123992919922	9.2567666015625	0.89540402404964	0.114808673970401	0.00452017039060593	0.150202928
327.123992919922	8.5082421875	0.845553469844162	0.109856868220959	0.00432538613677025	0.138057168
328.123992919922	7.7555244140625	0.795643369201571	0.104877100966405	0.00412924494594336	0.125843352
329.123992919922	6.99673974609375	0.745673663914204	0.099823359050788	0.00393028184771538	0.113531096
330.123992919922	6.236080078125	0.695823109708726	0.0947291118791327	0.00372969452291727	0.101188416
331.123992919922	5.4748037109375	0.645913009066135	0.089568377006799	0.00352651462890208	0.088835728
332.123992919922	4.71148681640625	0.596062454860657	0.0843407469801605	0.00332072586752474	0.076449928
333.123992919922	3.95043505859375	0.546092807780951	0.0790704943938181	0.00311323767527938	0.064100888
334.123992919922	3.19122412109375	0.496301800012589	0.0737094451324083	0.00290218438021839	0.051781712
335.123992919922	2.43276831054688	0.446451274910942	0.0682367171975784	0.00268662348389626	0.039474792
336.123992919922	1.67741271972656	0.396600720705464	0.0626402324996889	0.00246633822098374	0.027218178
337.123992919922	0.925640502929688	0.346571498084813	0.0568664145248476	0.0022390759550035	0.015019707
338.123992919922	0.182510101318359	0.296661397442222	0.0508577359141782	0.00200255680829287	0.002961461
339.123992919922	0.542416625976563	0.317983358399943	0.0534393802809063	0.0021036786492914	0.008801407
340.123992919922	1.3811025390625	0.36771479062736	0.0596115642110817	0.00234673661179841	0.022410164
341.123992919922	2.21710400390625	0.417505798395723	0.0655519907013513	0.00258055003359914	0.035975364
342.123992919922	3.04827880859375	0.467296777060255	0.0713300032657571	0.00280806608498096	0.04946224
343.123992919922	3.87533325195313	0.517266453243792	0.077004027843941	0.00303147942759097	0.062882264
344.123992919922	4.692763671875	0.567057461012155	0.0825641182018444	0.00325031182728708	0.07614612
345.123992919922	5.4997470703125	0.616788864135742	0.0879955405252986	0.00346419797278941	0.089240464
346.123992919922	6.2963330078125	0.666579871904105	0.0933416740735993	0.0036746587138623	0.102166096
347.123992919922	7.0829072265625	0.716370879672468	0.0985956503427587	0.00388152105733752	0.114929272
348.123992919922	7.85795703125	0.76616182923317	0.103764934465289	0.00408499641343951	0.127505456
349.123992919922	8.61868359375	0.815893290564418	0.108831380202901	0.00428455090150237	0.139849216
350.123992919922	9.3673251953125	0.865743844769895	0.11382076627342	0.00448093377053738	0.151996896
351.123992919922	10.10646875	0.915534794330597	0.118757045129314	0.00467522395774722	0.163990448
352.123992919922	10.833748046875	0.965385348536074	0.123609366710298	0.0048663318157196	0.175791488
353.123992919922	11.5558232421875	1.01511680986732	0.128448969917372	0.00505685107782483	0.18750808
354.123992919922	12.26618359375	1.0649673640728	0.133242589072324	0.00524562504142523	0.199034592
355.123992919922	12.9704970703125	1.11463922075927	0.137998606078327	0.00543285207822919	0.210462992
356.123992919922	13.6632734375	1.16443017031997	0.142748496728018	0.00561994686722755	0.221704176
357.123992919922	14.3475810546875	1.21416163165122	0.147494851262309	0.00580671848729253	0.232807936
358.123992919922	15.018767578125	1.2640121858567	0.152231805259362	0.00599319254979491	0.2436988
359.123992919922	15.6668193359375	1.3138031354174	0.15695471665822	0.00617910595610738	0.254214288
360.123992919922	16.26673828125	1.36365368962288	0.161809643032029	0.00637022312730551	0.263948736
361.123992919922	16.69903125	1.41350424382836	0.167527672601864	0.00659529026597738	0.270963232
362.123992919922	16.75167578125	1.46341440267861	0.17353700241074	0.00683198170736432	0.271817472
363.123992919922	16.772576171875	1.51338404975832	0.178576825419441	0.00703033152967691	0.272156608
364.123992919922	16.793533203125	1.56323460396379	0.183520765858702	0.0072250715456903	0.272496672
365.123992919922	16.811681640625	1.61326385568827	0.188412654097192	0.00741764903068542	0.272791136
366.123992919922	16.82831640625	1.66323350276798	0.1933493767865	0.00761200441047549	0.273061056
367.123992919922	16.842408203125	1.71326275449246	0.198252237169072	0.00780502241104841	0.273289728
368.123992919922	16.8557578125	1.76317279692739	0.203202711418271	0.00799988862127066	0.273506336
369.123992919922	16.869384765625	1.81320204865187	0.208179990295321	0.00819591153413057	0.273727456
370.123992919922	16.880591796875	1.86317169573158	0.21319578809198	0.00839336682111025	0.273909312
371.123992919922	16.89128125	1.91314134281129	0.21823869610671	0.00859184470027685	0.274082752
372.123992919922	16.901796875	1.96305150166154	0.223339491640218	0.00879260897636414	0.274253376
373.123992919922	16.913900390625	2.01308075338602	0.228488846914843	0.00899536721408367	0.27444976
374.123992919922	16.923693359375	2.0631100051105	0.233705039136112	0.00920076109468937	0.274608672
375.123992919922	16.93485546875	2.11307965219021	0.238999360590242	0.00940922275185585	0.274789792
376.123992919922	16.943857421875	2.16310890391469	0.244349561398849	0.00961992889642715	0.274935872
377.123992919922	16.954509765625	2.21313815563917	0.249817414442077	0.00983513612300158	0.275108704
378.123992919922	16.96302734375	2.26322677917778	0.255352671956643	0.0100530404597521	0.275246912
379.123992919922	16.973380859375	2.31307744979858	0.26098417583853	0.0102747483178973	0.275414912
380.123992919922	16.982388671875	2.36310670152307	0.266665243543684	0.0104984445497394	0.275561088
381.123992919922	16.993103515625	2.41307634860277	0.272510718787089	0.0107285222038627	0.275734944
382.123992919922	17.002708984375	2.46322457678616	0.278412771876901	0.0109608788043261	0.275890816
383.123992919922	17.012072265625	2.51313461922109	0.284444191493094	0.0111983446404338	0.276042752
384.123992919922	17.021150390625	2.56316387094557	0.290542840957642	0.0114384153857827	0.276190048
385.123992919922	17.03054296875	2.61313351802528	0.296793441521004	0.011684556491673	0.276342464
386.123992919922	17.040880859375	2.66316276974976	0.303113600239158	0.011933321133256	0.276510208
387.123992919922	17.049029296875	2.71313241682947	0.309535971609876	0.0121861901134253	0.2766424
388.123992919922	17.059892578125	2.76322127319872	0.316072284476832	0.0124435555189848	0.276818688
389.123992919922	17.068958984375	2.81319092027843	0.32271072268486	0.012704879976809	0.276965792
390.123992919922	17.079359375	2.86322017200291	0.329455535393208	0.0129704410210252	0.27713456
391.123992919922	17.08663671875	2.91324942372739	0.336259632604197	0.0132382484152913	0.27725264
392.123992919922	17.09727734375	2.96315946616232	0.343208783306181	0.0135119091719389	0.277425312
393.123992919922	17.10591796875	3.01324832253158	0.350214570062235	0.0137876803055406	0.277565504
394.123992919922	17.11715625	3.06321796961129	0.357381970388815	0.0140698831528425	0.277747872
395.123992919922	17.125060546875	3.11324722133577	0.364599720342085	0.0143540892750025	0.277876128
396.123992919922	17.134572265625	3.1631572637707	0.371982925571501	0.0146446246653795	0.278030464
397.123992919922	17.144166015625	3.21324612013996	0.379387784050778	0.0149362357333302	0.278186144
398.123992919922	17.152384765625	3.26321576721966	0.386985979275778	0.0152353718876839	0.278319488
399.123992919922	17.1621015625	3.31330462358892	0.394620787119493	0.0155360223725438	0.278477152
400.123992919922	17.170564453125	3.36327427066863	0.40240804082714	0.0158425159752369	0.278614464
401.123992919922	17.181189453125	3.41324391774833	0.410250853747129	0.0161513593047857	0.27878688
402.123992919922	17.18952734375	3.46327316947281	0.418248324422166	0.0164661183953285	0.278922176
403.123992919922	17.199451171875	3.51324281655252	0.42635016143322	0.0167851019650698	0.2790832
404.123992919922	17.2072421875	3.563272068277	0.434556568507105	0.0171081591397524	0.279209632
405.123992919922	17.217099609375	3.61330132000148	0.44289359357208	0.0174363404512405	0.279369568
406.123992919922	17.22451171875	3.6633899435401	0.451290019555017	0.0177670251578093	0.279489856
407.123992919922	17.235111328125	3.71329998597503	0.459854141809046	0.0181041490286589	0.279661824
408.123992919922	17.24344140625	3.76338884234428	0.468449929030612	0.0184425860643387	0.279796992
409.123992919922	17.252923828125	3.81335848942399	0.47718602581881	0.0187864936888218	0.27995088
410.123992919922	16.842947265625	3.81180993281305	0.479783426271752	0.0188893470913172	0.273298464
411.123992919922	16.107435546875	3.76184028573334	0.474916188977659	0.0186976958066225	0.26136384
412.123992919922	15.3981474609375	3.71193024329841	0.470034079626203	0.0185054410248995	0.249854736
413.123992919922	14.69688671875	3.66202020086348	0.46514134737663	0.0183128584176302	0.238475872
414.123992919922	14.003529296875	3.61216953024268	0.460267037851736	0.0181209016591311	0.227225264
415.123992919922	13.3114375	3.56219988316298	0.455392873845994	0.0179290510714054	0.215995184
416.123992919922	12.6199140625	3.5124090500176	0.45049810432829	0.017736304551363	0.20477432
417.123992919922	11.9281357421875	3.46249877475202	0.445603713160381	0.0175436493009329	0.193549328
418.123992919922	11.2337021484375	3.41264833696187	0.440684874774888	0.0173500012606382	0.182281248
419.123992919922	10.5416982421875	3.36267868988216	0.435747293522581	0.0171556361019611	0.171052608
420.123992919922	9.8483876953125	3.31282801926136	0.43079792521894	0.0169607531279325	0.159802752
421.123992919922	9.1556484375	3.26291797682643	0.425839069066569	0.016765533015132	0.14856216
422.123992919922	8.4633642578125	3.21312691085041	0.420848664361984	0.0165690518915653	0.13732896
423.123992919922	7.7693837890625	3.16327647306025	0.415866757975891	0.0163729470223188	0.12606824
424.123992919922	7.0707158203125	3.11342580243945	0.410794804338366	0.016173180192709	0.114731456
425.123992919922	6.36861376953125	3.0635753646493	0.405672704800963	0.0159715488553047	0.103338944
426.123992919922	5.66723974609375	3.01366532221437	0.400537246605381	0.015769399702549	0.091958248
427.123992919922	4.9684892578125	2.96381465159357	0.395370094338432	0.015566005371511	0.080620128
428.123992919922	4.269689453125	2.91396421380341	0.390146626159549	0.0153602957725525	0.0692812
429.123992919922	3.57582421875	2.86411354318261	0.384926795959473	0.0151548432186246	0.058022344
430.123992919922	2.88824462890625	2.81432247720659	0.379672186682001	0.0149479061365128	0.04686548
431.123992919922	2.19966235351563	2.76453164406121	0.374347262550145	0.0147382877767086	0.035692348
432.123992919922	1.5195322265625	2.71468097344041	0.368982349755242	0.0145271206274629	0.024656364
433.123992919922	0.845337829589844	2.66489014029503	0.363535596989095	0.014312569051981	0.013716693
434.123992919922	0.178404541015625	2.61492026038468	0.358032964868471	0.0140960142016411	0.002894843
435.123992919922	0.507778686523438	2.63368128798902	0.359866069629788	0.014167794957757	0.008239362
436.123992919922	1.31904162597656	2.68347235396504	0.365439685992897	0.0143872024491429	0.021403146
437.123992919922	2.12118017578125	2.73338239639997	0.37092057755217	0.0146029880270362	0.034418876
438.123992919922	2.91713403320313	2.783173462376	0.376340613001958	0.0148163652047515	0.047334248
439.123992919922	3.70382592773438	2.83308350481093	0.381680409191176	0.0150265945121646	0.060099336
440.123992919922	4.480021484375	2.88287457078695	0.386949424864724	0.0152340149506927	0.072694104
441.123992919922	5.24687744140625	2.93272500857711	0.392156303860247	0.015438973903656	0.085137328
442.123992919922	6.00530908203125	2.98245646990836	0.397293217247352	0.01564128883183	0.097443856
443.123992919922	6.7526640625	3.03224753588438	0.402356061385944	0.0158406291157007	0.109570656
444.123992919922	7.49039208984375	3.08191939257085	0.407389248721302	0.0160387121140957	0.12154124
445.123992919922	8.217529296875	3.13171045854688	0.412372726714239	0.0162349548190832	0.133339976
446.123992919922	8.933076171875	3.18138231523335	0.417278904933482	0.0164280869066715	0.14495064
447.123992919922	9.6382763671875	3.23129235766828	0.422141543822363	0.0166195370256901	0.156393424
448.123992919922	10.3339677734375	3.2810834236443	0.426969549153	0.0168096274137497	0.167681904
449.123992919922	11.0192666015625	3.33093386143446	0.431784079410136	0.0169992055743933	0.17880176
450.123992919922	11.6940927734375	3.38072492741048	0.436552712926641	0.0171869266778231	0.18975168
451.123992919922	12.36188671875	3.43045638874173	0.441292533650994	0.0173734854906797	0.200587504
452.123992919922	13.0174609375	3.48030682653189	0.446013465989381	0.0175593812018633	0.21122504
453.123992919922	13.665916015625	3.53009789250791	0.450757012004033	0.0177461076527834	0.221747056
454.123992919922	14.29672265625	3.57988872565329	0.45546458568424	0.0179315377026796	0.231982704
455.123992919922	14.9196435546875	3.62967979162931	0.46019785804674	0.0181177947670221	0.2420904
456.123992919922	15.517162109375	3.67958983406425	0.464946817373857	0.0183048136532307	0.251785904
457.123992919922	16.0889765625	3.72944050468504	0.469780468847603	0.0184951089322567	0.26106432
458.123992919922	16.599369140625	3.7792909424752	0.474726286483929	0.0186898801475763	0.269346112
459.123992919922	17.004998046875	3.82908200845122	0.480059010442346	0.0188997704535723	0.275927936
459.824005126953	17.1910078125	3.86404292657971	0.484149582916871	0.0190607961267233	0.278946208